Workbook

Sheet Dashboard
A1: ROADMAP HỌC THUẬT TOÁN ỨNG DỤNG – 100 NGÀY (C++ & Java)
A2: Chỉ sửa ô nền vàng. Mọi chỉ số khác tự cập nhật từ sheet Roadmap, LeetCode, NhatKy, Slide.
A3: CẤU HÌNH & HÔM NAY | D3: TIẾN ĐỘ THEO GIAI ĐOẠN
A4: Ngày bắt đầu (sửa ô này) | B4: 46300 | D4: Giai đoạn | E4: Số ngày | F4: Ngày xong | G4: % ngày | H4: Bài KH | I4: Bài xong | J4: % bài
A5: Ôn lần 1 sau (ngày) | B5: 3 | D5: 1. Nền tảng | E5: =COUNTIF(Roadmap!$C$5:$C$104,$D5) -> 10 | F5: =COUNTIFS(Roadmap!$C$5:$C$104,$D5,Roadmap!$P$5:$P$104,"Hoàn thành") -> 0 | G5: =IF(E5=0,0,F5/E5) -> 0 | H5: =COUNTIF(LeetCode!$B$5:$B$400,$D5) -> 37 | I5: =COUNTIFS(LeetCode!$B$5:$B$400,$D5,LeetCode!$H$5:$H$400,"Xong") -> 1 | J5: =IF(H5=0,0,I5/H5) -> 0.027027027
A6: Ôn lần 2 sau (ngày) | B6: 7 | D6: 2. CTDL & thuật toán kinh điển | E6: =COUNTIF(Roadmap!$C$5:$C$104,$D6) -> 18 | F6: =COUNTIFS(Roadmap!$C$5:$C$104,$D6,Roadmap!$P$5:$P$104,"Hoàn thành") -> 0 | G6: =IF(E6=0,0,F6/E6) -> 0 | H6: =COUNTIF(LeetCode!$B$5:$B$400,$D6) -> 69 | I6: =COUNTIFS(LeetCode!$B$5:$B$400,$D6,LeetCode!$H$5:$H$400,"Xong") -> 0 | J6: =IF(H6=0,0,I6/H6) -> 0
A7: Ôn lần 3 sau (ngày) | B7: 14 | D7: 3. RMQ & Segment Tree | E7: =COUNTIF(Roadmap!$C$5:$C$104,$D7) -> 6 | F7: =COUNTIFS(Roadmap!$C$5:$C$104,$D7,Roadmap!$P$5:$P$104,"Hoàn thành") -> 0 | G7: =IF(E7=0,0,F7/E7) -> 0 | H7: =COUNTIF(LeetCode!$B$5:$B$400,$D7) -> 17 | I7: =COUNTIFS(LeetCode!$B$5:$B$400,$D7,LeetCode!$H$5:$H$400,"Xong") -> 0 | J7: =IF(H7=0,0,I7/H7) -> 0
A8: Hôm nay là ngày thứ | B8: =MAX(0,TODAY()-B4+1) -> 1 | D8: 4. Quay lui & Nhánh cận | E8: =COUNTIF(Roadmap!$C$5:$C$104,$D8) -> 10 | F8: =COUNTIFS(Roadmap!$C$5:$C$104,$D8,Roadmap!$P$5:$P$104,"Hoàn thành") -> 0 | G8: =IF(E8=0,0,F8/E8) -> 0 | H8: =COUNTIF(LeetCode!$B$5:$B$400,$D8) -> 34 | I8: =COUNTIFS(LeetCode!$B$5:$B$400,$D8,LeetCode!$H$5:$H$400,"Xong") -> 0 | J8: =IF(H8=0,0,I8/H8) -> 0
A9: Chủ đề hôm nay | B9: =IF(B8<1,"Chưa bắt đầu",IF(B8>100,"Đã hết 100 ngày",INDEX(Roadmap!$D$5:$D$104,B8))) -> Môi trường, I/O nhanh, độ phức tạp Big-O | D9: 5. Tham lam | E9: =COUNTIF(Roadmap!$C$5:$C$104,$D9) -> 7 | F9: =COUNTIFS(Roadmap!$C$5:$C$104,$D9,Roadmap!$P$5:$P$104,"Hoàn thành") -> 0 | G9: =IF(E9=0,0,F9/E9) -> 0 | H9: =COUNTIF(LeetCode!$B$5:$B$400,$D9) -> 27 | I9: =COUNTIFS(LeetCode!$B$5:$B$400,$D9,LeetCode!$H$5:$H$400,"Xong") -> 0 | J9: =IF(H9=0,0,I9/H9) -> 0
A10: Bài LeetCode hôm nay | B10: =IF(AND(B8>=1,B8<=100),INDEX(Roadmap!$I$5:$I$104,B8),"-") -> 1, 412, 217 | D10: 6. Chia để trị | E10: =COUNTIF(Roadmap!$C$5:$C$104,$D10) -> 5 | F10: =COUNTIFS(Roadmap!$C$5:$C$104,$D10,Roadmap!$P$5:$P$104,"Hoàn thành") -> 0 | G10: =IF(E10=0,0,F10/E10) -> 0 | H10: =COUNTIF(LeetCode!$B$5:$B$400,$D10) -> 17 | I10: =COUNTIFS(LeetCode!$B$5:$B$400,$D10,LeetCode!$H$5:$H$400,"Xong") -> 0 | J10: =IF(H10=0,0,I10/H10) -> 0
A11: Ngày kết thúc dự kiến | B11: =B4+99 -> 46399 | D11: 7. Quy hoạch động | E11: =COUNTIF(Roadmap!$C$5:$C$104,$D11) -> 17 | F11: =COUNTIFS(Roadmap!$C$5:$C$104,$D11,Roadmap!$P$5:$P$104,"Hoàn thành") -> 0 | G11: =IF(E11=0,0,F11/E11) -> 0 | H11: =COUNTIF(LeetCode!$B$5:$B$400,$D11) -> 63 | I11: =COUNTIFS(LeetCode!$B$5:$B$400,$D11,LeetCode!$H$5:$H$400,"Xong") -> 0 | J11: =IF(H11=0,0,I11/H11) -> 0
D12: 8. Đồ thị, DFS & Cây | E12: =COUNTIF(Roadmap!$C$5:$C$104,$D12) -> 13 | F12: =COUNTIFS(Roadmap!$C$5:$C$104,$D12,Roadmap!$P$5:$P$104,"Hoàn thành") -> 0 | G12: =IF(E12=0,0,F12/E12) -> 0 | H12: =COUNTIF(LeetCode!$B$5:$B$400,$D12) -> 47 | I12: =COUNTIFS(LeetCode!$B$5:$B$400,$D12,LeetCode!$H$5:$H$400,"Xong") -> 0 | J12: =IF(H12=0,0,I12/H12) -> 0
A13: TIẾN ĐỘ LỘ TRÌNH | D13: 9. Luồng & Ghép cặp | E13: =COUNTIF(Roadmap!$C$5:$C$104,$D13) -> 4 | F13: =COUNTIFS(Roadmap!$C$5:$C$104,$D13,Roadmap!$P$5:$P$104,"Hoàn thành") -> 0 | G13: =IF(E13=0,0,F13/E13) -> 0 | H13: =COUNTIF(LeetCode!$B$5:$B$400,$D13) -> 5 | I13: =COUNTIFS(LeetCode!$B$5:$B$400,$D13,LeetCode!$H$5:$H$400,"Xong") -> 0 | J13: =IF(H13=0,0,I13/H13) -> 0
A14: Số ngày hoàn thành | B14: =COUNTIF(Roadmap!$P$5:$P$104,"Hoàn thành") -> 0 | D14: 10. Hình học | E14: =COUNTIF(Roadmap!$C$5:$C$104,$D14) -> 3 | F14: =COUNTIFS(Roadmap!$C$5:$C$104,$D14,Roadmap!$P$5:$P$104,"Hoàn thành") -> 0 | G14: =IF(E14=0,0,F14/E14) -> 0 | H14: =COUNTIF(LeetCode!$B$5:$B$400,$D14) -> 10 | I14: =COUNTIFS(LeetCode!$B$5:$B$400,$D14,LeetCode!$H$5:$H$400,"Xong") -> 0 | J14: =IF(H14=0,0,I14/H14) -> 0
A15: % lộ trình hoàn thành | B15: =B14/COUNT(Roadmap!$A$5:$A$104) -> 0 | D15: 11. Xâu | E15: =COUNTIF(Roadmap!$C$5:$C$104,$D15) -> 4 | F15: =COUNTIFS(Roadmap!$C$5:$C$104,$D15,Roadmap!$P$5:$P$104,"Hoàn thành") -> 0 | G15: =IF(E15=0,0,F15/E15) -> 0 | H15: =COUNTIF(LeetCode!$B$5:$B$400,$D15) -> 11 | I15: =COUNTIFS(LeetCode!$B$5:$B$400,$D15,LeetCode!$H$5:$H$400,"Xong") -> 0 | J15: =IF(H15=0,0,I15/H15) -> 0
A16: Số ngày theo lịch đã qua (không tính hôm nay) | B16: =MIN(100,MAX(0,B8-1)) -> 0 | D16: 12. NP-đầy đủ & Tổng ôn | E16: =COUNTIF(Roadmap!$C$5:$C$104,$D16) -> 3 | F16: =COUNTIFS(Roadmap!$C$5:$C$104,$D16,Roadmap!$P$5:$P$104,"Hoàn thành") -> 0 | G16: =IF(E16=0,0,F16/E16) -> 0 | H16: =COUNTIF(LeetCode!$B$5:$B$400,$D16) -> 1 | I16: =COUNTIFS(LeetCode!$B$5:$B$400,$D16,LeetCode!$H$5:$H$400,"Xong") -> 0 | J16: =IF(H16=0,0,I16/H16) -> 0
A17: Chênh lệch so với kế hoạch (+ là vượt tiến độ) | B17: =B14-B16 -> 0
A18: Số ngày trễ hạn | B18: =COUNTIF(Roadmap!$P$5:$P$104,"Trễ hạn") -> 0 | D18: THEO ĐỘ KHÓ
D19: Độ khó | E19: Tổng | F19: Xong | G19: %
A20: LEETCODE | D20: Easy | E20: =COUNTIF(LeetCode!$F$5:$F$400,$D20) -> 58 | F20: =COUNTIFS(LeetCode!$F$5:$F$400,$D20,LeetCode!$H$5:$H$400,"Xong") -> 1 | G20: =IF(E20=0,0,F20/E20) -> 0.017241379
A21: Tổng bài kế hoạch | B21: =COUNTA(LeetCode!$D$5:$D$400) -> 338 | D21: Medium | E21: =COUNTIF(LeetCode!$F$5:$F$400,$D21) -> 199 | F21: =COUNTIFS(LeetCode!$F$5:$F$400,$D21,LeetCode!$H$5:$H$400,"Xong") -> 0 | G21: =IF(E21=0,0,F21/E21) -> 0
A22: Đã xong | B22: =COUNTIF(LeetCode!$H$5:$H$400,"Xong") -> 1 | D22: Hard | E22: =COUNTIF(LeetCode!$F$5:$F$400,$D22) -> 81 | F22: =COUNTIFS(LeetCode!$F$5:$F$400,$D22,LeetCode!$H$5:$H$400,"Xong") -> 0 | G22: =IF(E22=0,0,F22/E22) -> 0
A23: % hoàn thành | B23: =IF(B21=0,0,B22/B21) -> 0.0029585799
A24: Đang ở trạng thái Cần ôn | B24: =COUNTIF(LeetCode!$H$5:$H$400,"Cần ôn") -> 0 | D24: GIỜ HỌC & BÀI GIẢI THEO TUẦN
A25: Số lần thử trung bình / bài đã xong | B25: =IF(COUNTIFS(LeetCode!$H$5:$H$400,"Xong",LeetCode!$L$5:$L$400,">0")=0,0,SUMIFS(LeetCode!$L$5:$L$400,LeetCode!$H$5:$H$400,"Xong",LeetCode!$L$5:$L$400,">0")/COUNTIFS(LeetCode!$H$5:$H$400,"Xong",LeetCode!$L$5:$L$400,">0")) -> 1 | D25: Tuần | E25: Giờ KH | F25: Giờ thực tế | G25: Bài giải
A26: Bài đến hạn ôn hôm nay | B26: =COUNTIF(LeetCode!$Q$5:$Q$400,TODAY()) -> 0 | D26: 1 | E26: =SUMIFS(NhatKy!$E$5:$E$104,NhatKy!$C$5:$C$104,$D26) -> 21 | F26: =SUMIFS(NhatKy!$D$5:$D$104,NhatKy!$C$5:$C$104,$D26) -> 0 | G26: =SUMIFS(NhatKy!$F$5:$F$104,NhatKy!$C$5:$C$104,$D26) -> 1
A27: Dự kiến xong hết bài (theo tốc độ hiện tại) | B27: =IF(OR(B22=0,B16=0),"-",B4+ROUNDUP(B21/(B22/B16),0)-1) -> - | D27: 2 | E27: =SUMIFS(NhatKy!$E$5:$E$104,NhatKy!$C$5:$C$104,$D27) -> 21 | F27: =SUMIFS(NhatKy!$D$5:$D$104,NhatKy!$C$5:$C$104,$D27) -> 0 | G27: =SUMIFS(NhatKy!$F$5:$F$104,NhatKy!$C$5:$C$104,$D27) -> 0
D28: 3 | E28: =SUMIFS(NhatKy!$E$5:$E$104,NhatKy!$C$5:$C$104,$D28) -> 21 | F28: =SUMIFS(NhatKy!$D$5:$D$104,NhatKy!$C$5:$C$104,$D28) -> 0 | G28: =SUMIFS(NhatKy!$F$5:$F$104,NhatKy!$C$5:$C$104,$D28) -> 0
A29: GIỜ HỌC & KỶ LUẬT | D29: 4 | E29: =SUMIFS(NhatKy!$E$5:$E$104,NhatKy!$C$5:$C$104,$D29) -> 21 | F29: =SUMIFS(NhatKy!$D$5:$D$104,NhatKy!$C$5:$C$104,$D29) -> 0 | G29: =SUMIFS(NhatKy!$F$5:$F$104,NhatKy!$C$5:$C$104,$D29) -> 0
A30: Tổng giờ kế hoạch | B30: =SUM(Roadmap!$Q$5:$Q$104) -> 302 | D30: 5 | E30: =SUMIFS(NhatKy!$E$5:$E$104,NhatKy!$C$5:$C$104,$D30) -> 21 | F30: =SUMIFS(NhatKy!$D$5:$D$104,NhatKy!$C$5:$C$104,$D30) -> 0 | G30: =SUMIFS(NhatKy!$F$5:$F$104,NhatKy!$C$5:$C$104,$D30) -> 0
A31: Tổng giờ thực tế | B31: =SUM(NhatKy!$D$5:$D$104) -> 0 | D31: 6 | E31: =SUMIFS(NhatKy!$E$5:$E$104,NhatKy!$C$5:$C$104,$D31) -> 21 | F31: =SUMIFS(NhatKy!$D$5:$D$104,NhatKy!$C$5:$C$104,$D31) -> 0 | G31: =SUMIFS(NhatKy!$F$5:$F$104,NhatKy!$C$5:$C$104,$D31) -> 0
A32: Giờ trung bình / ngày có học | B32: =IF(COUNTIF(NhatKy!$D$5:$D$104,">0")=0,0,B31/COUNTIF(NhatKy!$D$5:$D$104,">0")) -> 0 | D32: 7 | E32: =SUMIFS(NhatKy!$E$5:$E$104,NhatKy!$C$5:$C$104,$D32) -> 21 | F32: =SUMIFS(NhatKy!$D$5:$D$104,NhatKy!$C$5:$C$104,$D32) -> 0 | G32: =SUMIFS(NhatKy!$F$5:$F$104,NhatKy!$C$5:$C$104,$D32) -> 0
A33: Chuỗi ngày học liên tiếp hiện tại | B33: =IF(OR(B8<1,B8>100),0,IF(INDEX(NhatKy!$D$5:$D$104,B8)>0,INDEX(NhatKy!$J$5:$J$104,B8),IF(B8>1,INDEX(NhatKy!$J$5:$J$104,B8-1),0))) -> 0 | D33: 8 | E33: =SUMIFS(NhatKy!$E$5:$E$104,NhatKy!$C$5:$C$104,$D33) -> 21 | F33: =SUMIFS(NhatKy!$D$5:$D$104,NhatKy!$C$5:$C$104,$D33) -> 0 | G33: =SUMIFS(NhatKy!$F$5:$F$104,NhatKy!$C$5:$C$104,$D33) -> 0
A34: Chuỗi dài nhất | B34: =MAX(NhatKy!$J$5:$J$104) -> 0 | D34: 9 | E34: =SUMIFS(NhatKy!$E$5:$E$104,NhatKy!$C$5:$C$104,$D34) -> 21 | F34: =SUMIFS(NhatKy!$D$5:$D$104,NhatKy!$C$5:$C$104,$D34) -> 0 | G34: =SUMIFS(NhatKy!$F$5:$F$104,NhatKy!$C$5:$C$104,$D34) -> 0
D35: 10 | E35: =SUMIFS(NhatKy!$E$5:$E$104,NhatKy!$C$5:$C$104,$D35) -> 21 | F35: =SUMIFS(NhatKy!$D$5:$D$104,NhatKy!$C$5:$C$104,$D35) -> 0 | G35: =SUMIFS(NhatKy!$F$5:$F$104,NhatKy!$C$5:$C$104,$D35) -> 0
A36: CHECKLIST SLIDE | D36: 11 | E36: =SUMIFS(NhatKy!$E$5:$E$104,NhatKy!$C$5:$C$104,$D36) -> 21 | F36: =SUMIFS(NhatKy!$D$5:$D$104,NhatKy!$C$5:$C$104,$D36) -> 0 | G36: =SUMIFS(NhatKy!$F$5:$F$104,NhatKy!$C$5:$C$104,$D36) -> 0
A37: Tổng mục slide | B37: =COUNTA(Slide!$C$5:$C$60) -> 24 | D37: 12 | E37: =SUMIFS(NhatKy!$E$5:$E$104,NhatKy!$C$5:$C$104,$D37) -> 21 | F37: =SUMIFS(NhatKy!$D$5:$D$104,NhatKy!$C$5:$C$104,$D37) -> 0 | G37: =SUMIFS(NhatKy!$F$5:$F$104,NhatKy!$C$5:$C$104,$D37) -> 0
A38: Mục đã nắm đủ (4 dấu ✓) | B38: =COUNTIFS(Slide!$H$5:$H$60,"✓",Slide!$I$5:$I$60,"✓",Slide!$J$5:$J$60,"✓",Slide!$K$5:$K$60,"✓") -> 0 | D38: 13 | E38: =SUMIFS(NhatKy!$E$5:$E$104,NhatKy!$C$5:$C$104,$D38) -> 21 | F38: =SUMIFS(NhatKy!$D$5:$D$104,NhatKy!$C$5:$C$104,$D38) -> 0 | G38: =SUMIFS(NhatKy!$F$5:$F$104,NhatKy!$C$5:$C$104,$D38) -> 0
A39: % mục slide | B39: =IF(B37=0,0,B38/B37) -> 0 | D39: 14 | E39: =SUMIFS(NhatKy!$E$5:$E$104,NhatKy!$C$5:$C$104,$D39) -> 21 | F39: =SUMIFS(NhatKy!$D$5:$D$104,NhatKy!$C$5:$C$104,$D39) -> 0 | G39: =SUMIFS(NhatKy!$F$5:$F$104,NhatKy!$C$5:$C$104,$D39) -> 0
D40: 15 | E40: =SUMIFS(NhatKy!$E$5:$E$104,NhatKy!$C$5:$C$104,$D40) -> 8 | F40: =SUMIFS(NhatKy!$D$5:$D$104,NhatKy!$C$5:$C$104,$D40) -> 0 | G40: =SUMIFS(NhatKy!$F$5:$F$104,NhatKy!$C$5:$C$104,$D40) -> 0

Sheet Roadmap
A1: LỘ TRÌNH 100 NGÀY – THUẬT TOÁN ỨNG DỤNG (C++ & Java)
A2: Ô nền vàng = bạn nhập. Dòng nền xanh nhạt = hôm nay. Trạng thái ngày tự tính từ các ô ✓ và sheet LeetCode.
A4: Ngày | B4: Ngày dự kiến | C4: Giai đoạn | D4: Chủ đề | E4: Nội dung lý thuyết cần học | F4: Nguồn | G4: Gợi ý C++ | H4: Gợi ý Java | I4: Bài LeetCode (#) | J4: Bài ngoài LeetCode / lưu ý | K4: Số bài KH | L4: Số bài xong | M4: Lý thuyết ✓ | N4: C++ ✓ | O4: Java ✓ | P4: Trạng thái | Q4: Giờ KH | R4: Giờ thực tế | S4: Ghi chú
A5: 1 | B5: =Dashboard!$B$4+A5-1 -> 46300 | C5: 1. Nền tảng | D5: Môi trường, I/O nhanh, độ phức tạp Big-O | E5: Cài g++/JDK + IDE; viết template thi; Big-O; ~10^8 phép/giây; ôn thư viện chuẩn (Chương 1) | F5: Slide T1 (Chương 1) + Kiến thức nền | G5: bits/stdc++.h, sync_with_stdio(false), vector, pair | H5: BufferedReader, StringTokenizer, StringBuilder | I5: 1, 412, 217 | J5: Tạo template C++ và Java dùng cho cả khoá | K5: =COUNTIF(LeetCode!$A$5:$A$400,A5) -> 3 | L5: =COUNTIFS(LeetCode!$A$5:$A$400,A5,LeetCode!$H$5:$H$400,"Xong") -> 1 | P5: =IF(AND(M5="✓",N5="✓",O5="✓",L5>=K5),"Hoàn thành",IF(B5<TODAY(),"Trễ hạn",IF(OR(M5="✓",N5="✓",O5="✓",L5>0),"Đang học","Chưa bắt đầu"))) -> Đang học | Q5: 3 | R5: =IF(NhatKy!D5="","",NhatKy!D5)
A6: 2 | B6: =Dashboard!$B$4+A6-1 -> 46301 | C6: 1. Nền tảng | D6: Mảng 1 chiều & kỹ thuật in-place | E6: Duyệt, xoá phần tử, dồn mảng, gộp 2 mảng đã sắp xếp | F6: Kiến thức nền | G6: vector, erase, swap, reverse | H6: int[], Arrays.fill/copyOf, System.arraycopy | I6: 26, 27, 88, 283 | K6: =COUNTIF(LeetCode!$A$5:$A$400,A6) -> 4 | L6: =COUNTIFS(LeetCode!$A$5:$A$400,A6,LeetCode!$H$5:$H$400,"Xong") -> 0 | P6: =IF(AND(M6="✓",N6="✓",O6="✓",L6>=K6),"Hoàn thành",IF(B6<TODAY(),"Trễ hạn",IF(OR(M6="✓",N6="✓",O6="✓",L6>0),"Đang học","Chưa bắt đầu"))) -> Chưa bắt đầu | Q6: 3 | R6: =IF(NhatKy!D6="","",NhatKy!D6)
A7: 3 | B7: =Dashboard!$B$4+A7-1 -> 46302 | C7: 1. Nền tảng | D7: Xâu ký tự cơ bản | E7: Duyệt xâu, bảng đếm 26 ký tự, palindrome, tiền tố chung | F7: Kiến thức nền | G7: string, substr, array<int,26> | H7: String, StringBuilder, toCharArray | I7: 344, 125, 242, 14 | K7: =COUNTIF(LeetCode!$A$5:$A$400,A7) -> 4 | L7: =COUNTIFS(LeetCode!$A$5:$A$400,A7,LeetCode!$H$5:$H$400,"Xong") -> 0 | P7: =IF(AND(M7="✓",N7="✓",O7="✓",L7>=K7),"Hoàn thành",IF(B7<TODAY(),"Trễ hạn",IF(OR(M7="✓",N7="✓",O7="✓",L7>0),"Đang học","Chưa bắt đầu"))) -> Chưa bắt đầu | Q7: 3 | R7: =IF(NhatKy!D7="","",NhatKy!D7)
A8: 4 | B8: =Dashboard!$B$4+A8-1 -> 46303 | C8: 1. Nền tảng | D8: Số học cơ bản & tràn số | E8: Đảo số, chia lấy dư, tràn int → dùng long long / long | F8: Kiến thức nền | G8: long long, INT_MAX, abs | H8: long, Math.addExact, Integer.MAX_VALUE | I8: 9, 13, 7, 66 | K8: =COUNTIF(LeetCode!$A$5:$A$400,A8) -> 4 | L8: =COUNTIFS(LeetCode!$A$5:$A$400,A8,LeetCode!$H$5:$H$400,"Xong") -> 0 | P8: =IF(AND(M8="✓",N8="✓",O8="✓",L8>=K8),"Hoàn thành",IF(B8<TODAY(),"Trễ hạn",IF(OR(M8="✓",N8="✓",O8="✓",L8>0),"Đang học","Chưa bắt đầu"))) -> Chưa bắt đầu | Q8: 3 | R8: =IF(NhatKy!D8="","",NhatKy!D8)
A9: 5 | B9: =Dashboard!$B$4+A9-1 -> 46304 | C9: 1. Nền tảng | D9: GCD, luỹ thừa nhanh, sàng nguyên tố | E9: Euclid; binary exponentiation O(log n); sàng Eratosthenes O(n log log n); modulo | F9: Kiến thức nền | G9: gcd, vector<bool> | H9: boolean[], Math.sqrt, BigInteger | I9: 204, 50, 69, 1071 | K9: =COUNTIF(LeetCode!$A$5:$A$400,A9) -> 4 | L9: =COUNTIFS(LeetCode!$A$5:$A$400,A9,LeetCode!$H$5:$H$400,"Xong") -> 0 | P9: =IF(AND(M9="✓",N9="✓",O9="✓",L9>=K9),"Hoàn thành",IF(B9<TODAY(),"Trễ hạn",IF(OR(M9="✓",N9="✓",O9="✓",L9>0),"Đang học","Chưa bắt đầu"))) -> Chưa bắt đầu | Q9: 3 | R9: =IF(NhatKy!D9="","",NhatKy!D9)
A10: 6 | B10: =Dashboard!$B$4+A10-1 -> 46305 | C10: 1. Nền tảng | D10: Prefix sum & difference array | E10: Tổng tiền tố, truy vấn đoạn O(1), prefix + hash map | F10: Kiến thức nền | G10: partial_sum, unordered_map | H10: long[] prefix, HashMap | I10: 303, 724, 238, 560 | K10: =COUNTIF(LeetCode!$A$5:$A$400,A10) -> 4 | L10: =COUNTIFS(LeetCode!$A$5:$A$400,A10,LeetCode!$H$5:$H$400,"Xong") -> 0 | P10: =IF(AND(M10="✓",N10="✓",O10="✓",L10>=K10),"Hoàn thành",IF(B10<TODAY(),"Trễ hạn",IF(OR(M10="✓",N10="✓",O10="✓",L10>0),"Đang học","Chưa bắt đầu"))) -> Chưa bắt đầu | Q10: 3 | R10: =IF(NhatKy!D10="","",NhatKy!D10)
A11: 7 | B11: =Dashboard!$B$4+A11-1 -> 46306 | C11: 1. Nền tảng | D11: Kadane + ôn tập tuần 1 | E11: Kadane O(n); làm lại bài sai; viết lại template | F11: Kiến thức nền | G11: max/min, INT_MIN | H11: Math.max/min, Integer.MIN_VALUE | I11: 53, 121, 169 | J11: Giải thích lại 3 kỹ thuật tuần này không nhìn tài liệu | K11: =COUNTIF(LeetCode!$A$5:$A$400,A11) -> 3 | L11: =COUNTIFS(LeetCode!$A$5:$A$400,A11,LeetCode!$H$5:$H$400,"Xong") -> 0 | P11: =IF(AND(M11="✓",N11="✓",O11="✓",L11>=K11),"Hoàn thành",IF(B11<TODAY(),"Trễ hạn",IF(OR(M11="✓",N11="✓",O11="✓",L11>0),"Đang học","Chưa bắt đầu"))) -> Chưa bắt đầu | Q11: 3 | R11: =IF(NhatKy!D11="","",NhatKy!D11)
A12: 8 | B12: =Dashboard!$B$4+A12-1 -> 46307 | C12: 1. Nền tảng | D12: Hai con trỏ | E12: Mảng đã sắp xếp; left/right; loại trùng trong 3Sum | F12: Kiến thức nền | G12: sort, vector | H12: Arrays.sort | I12: 167, 15, 11 | K12: =COUNTIF(LeetCode!$A$5:$A$400,A12) -> 3 | L12: =COUNTIFS(LeetCode!$A$5:$A$400,A12,LeetCode!$H$5:$H$400,"Xong") -> 0 | P12: =IF(AND(M12="✓",N12="✓",O12="✓",L12>=K12),"Hoàn thành",IF(B12<TODAY(),"Trễ hạn",IF(OR(M12="✓",N12="✓",O12="✓",L12>0),"Đang học","Chưa bắt đầu"))) -> Chưa bắt đầu | Q12: 3 | R12: =IF(NhatKy!D12="","",NhatKy!D12)
A13: 9 | B13: =Dashboard!$B$4+A13-1 -> 46308 | C13: 1. Nền tảng | D13: Cửa sổ trượt | E13: Cửa sổ cố định / co giãn; đếm tần suất ký tự | F13: Kiến thức nền | G13: unordered_map, array<int,128> | H13: HashMap, int[128] | I13: 3, 209, 567, 76 | K13: =COUNTIF(LeetCode!$A$5:$A$400,A13) -> 4 | L13: =COUNTIFS(LeetCode!$A$5:$A$400,A13,LeetCode!$H$5:$H$400,"Xong") -> 0 | P13: =IF(AND(M13="✓",N13="✓",O13="✓",L13>=K13),"Hoàn thành",IF(B13<TODAY(),"Trễ hạn",IF(OR(M13="✓",N13="✓",O13="✓",L13>0),"Đang học","Chưa bắt đầu"))) -> Chưa bắt đầu | Q13: 3 | R13: =IF(NhatKy!D13="","",NhatKy!D13)
A14: 10 | B14: =Dashboard!$B$4+A14-1 -> 46309 | C14: 1. Nền tảng | D14: Đệ quy cơ bản | E14: Điều kiện dừng, cây đệ quy, memo hoá, độ sâu ngăn xếp | F14: Kiến thức nền | G14: đệ quy; chú ý độ sâu ~10^5 | H14: StackOverflowError → new Thread(..., stackSize) | I14: 509, 70, 231, 779 | K14: =COUNTIF(LeetCode!$A$5:$A$400,A14) -> 4 | L14: =COUNTIFS(LeetCode!$A$5:$A$400,A14,LeetCode!$H$5:$H$400,"Xong") -> 0 | P14: =IF(AND(M14="✓",N14="✓",O14="✓",L14>=K14),"Hoàn thành",IF(B14<TODAY(),"Trễ hạn",IF(OR(M14="✓",N14="✓",O14="✓",L14>0),"Đang học","Chưa bắt đầu"))) -> Chưa bắt đầu | Q14: 3 | R14: =IF(NhatKy!D14="","",NhatKy!D14)
A15: 11 | B15: =Dashboard!$B$4+A15-1 -> 46310 | C15: 2. CTDL & thuật toán kinh điển | D15: Tìm kiếm nhị phân cơ bản | E15: Biên lo/hi, mid=lo+(hi-lo)/2, bất biến vòng lặp | F15: CTDL & thuật toán kinh điển | G15: lower_bound, upper_bound, binary_search | H15: Arrays.binarySearch (tự viết lower_bound) | I15: 704, 35, 34, 74 | K15: =COUNTIF(LeetCode!$A$5:$A$400,A15) -> 4 | L15: =COUNTIFS(LeetCode!$A$5:$A$400,A15,LeetCode!$H$5:$H$400,"Xong") -> 0 | P15: =IF(AND(M15="✓",N15="✓",O15="✓",L15>=K15),"Hoàn thành",IF(B15<TODAY(),"Trễ hạn",IF(OR(M15="✓",N15="✓",O15="✓",L15>0),"Đang học","Chưa bắt đầu"))) -> Chưa bắt đầu | Q15: 3 | R15: =IF(NhatKy!D15="","",NhatKy!D15)
A16: 12 | B16: =Dashboard!$B$4+A16-1 -> 46311 | C16: 2. CTDL & thuật toán kinh điển | D16: Tìm kiếm nhị phân trên đáp án | E16: Hàm đơn điệu feasible(x); mảng xoay; chia tỉ lệ | F16: CTDL & thuật toán kinh điển | G16: lambda, long long | H16: hàm kiểm tra tự viết | I16: 33, 153, 875, 4 | K16: =COUNTIF(LeetCode!$A$5:$A$400,A16) -> 4 | L16: =COUNTIFS(LeetCode!$A$5:$A$400,A16,LeetCode!$H$5:$H$400,"Xong") -> 0 | P16: =IF(AND(M16="✓",N16="✓",O16="✓",L16>=K16),"Hoàn thành",IF(B16<TODAY(),"Trễ hạn",IF(OR(M16="✓",N16="✓",O16="✓",L16>0),"Đang học","Chưa bắt đầu"))) -> Chưa bắt đầu | Q16: 3 | R16: =IF(NhatKy!D16="","",NhatKy!D16)
A17: 13 | B17: =Dashboard!$B$4+A17-1 -> 46312 | C17: 2. CTDL & thuật toán kinh điển | D17: Sắp xếp & comparator tuỳ biến | E17: Merge/Quick/Heap sort; sắp xếp ổn định; quickselect | F17: CTDL & thuật toán kinh điển | G17: sort, stable_sort, lambda | H17: Arrays.sort(T[], Comparator), Collections.sort | I17: 912, 75, 215, 56 | K17: =COUNTIF(LeetCode!$A$5:$A$400,A17) -> 4 | L17: =COUNTIFS(LeetCode!$A$5:$A$400,A17,LeetCode!$H$5:$H$400,"Xong") -> 0 | P17: =IF(AND(M17="✓",N17="✓",O17="✓",L17>=K17),"Hoàn thành",IF(B17<TODAY(),"Trễ hạn",IF(OR(M17="✓",N17="✓",O17="✓",L17>0),"Đang học","Chưa bắt đầu"))) -> Chưa bắt đầu | Q17: 3 | R17: =IF(NhatKy!D17="","",NhatKy!D17)
A18: 14 | B18: =Dashboard!$B$4+A18-1 -> 46313 | C18: 2. CTDL & thuật toán kinh điển | D18: Ôn tập tuần 2 + xử lý ma trận | E18: Duyệt xoắn ốc, xoay ma trận, đánh dấu in-place; ôn 3 bài sai | F18: CTDL & thuật toán kinh điển | G18: vector<vector<int>> | H18: int[][] | I18: 189, 48, 54, 73 | K18: =COUNTIF(LeetCode!$A$5:$A$400,A18) -> 4 | L18: =COUNTIFS(LeetCode!$A$5:$A$400,A18,LeetCode!$H$5:$H$400,"Xong") -> 0 | P18: =IF(AND(M18="✓",N18="✓",O18="✓",L18>=K18),"Hoàn thành",IF(B18<TODAY(),"Trễ hạn",IF(OR(M18="✓",N18="✓",O18="✓",L18>0),"Đang học","Chưa bắt đầu"))) -> Chưa bắt đầu | Q18: 3 | R18: =IF(NhatKy!D18="","",NhatKy!D18)
A19: 15 | B19: =Dashboard!$B$4+A19-1 -> 46314 | C19: 2. CTDL & thuật toán kinh điển | D19: Stack | E19: LIFO; kiểm tra ngoặc; biểu thức hậu tố | F19: CTDL & thuật toán kinh điển | G19: stack, vector làm stack | H19: ArrayDeque làm stack (tránh class Stack) | I19: 20, 155, 150, 71 | K19: =COUNTIF(LeetCode!$A$5:$A$400,A19) -> 4 | L19: =COUNTIFS(LeetCode!$A$5:$A$400,A19,LeetCode!$H$5:$H$400,"Xong") -> 0 | P19: =IF(AND(M19="✓",N19="✓",O19="✓",L19>=K19),"Hoàn thành",IF(B19<TODAY(),"Trễ hạn",IF(OR(M19="✓",N19="✓",O19="✓",L19>0),"Đang học","Chưa bắt đầu"))) -> Chưa bắt đầu | Q19: 3 | R19: =IF(NhatKy!D19="","",NhatKy!D19)
A20: 16 | B20: =Dashboard!$B$4+A20-1 -> 46315 | C20: 2. CTDL & thuật toán kinh điển | D20: Monotonic stack | E20: Phần tử lớn kế tiếp; histogram; mỗi phần tử vào/ra ngăn xếp 1 lần | F20: CTDL & thuật toán kinh điển | G20: stack<int> lưu chỉ số | H20: Deque<Integer> lưu chỉ số | I20: 739, 496, 503, 84 | K20: =COUNTIF(LeetCode!$A$5:$A$400,A20) -> 4 | L20: =COUNTIFS(LeetCode!$A$5:$A$400,A20,LeetCode!$H$5:$H$400,"Xong") -> 0 | P20: =IF(AND(M20="✓",N20="✓",O20="✓",L20>=K20),"Hoàn thành",IF(B20<TODAY(),"Trễ hạn",IF(OR(M20="✓",N20="✓",O20="✓",L20>0),"Đang học","Chưa bắt đầu"))) -> Chưa bắt đầu | Q20: 3 | R20: =IF(NhatKy!D20="","",NhatKy!D20)
A21: 17 | B21: =Dashboard!$B$4+A21-1 -> 46316 | C21: 2. CTDL & thuật toán kinh điển | D21: Queue & Deque | E21: Hàng đợi; deque đơn điệu cho sliding window max | F21: CTDL & thuật toán kinh điển | G21: queue, deque | H21: Queue, ArrayDeque | I21: 232, 225, 622, 239 | K21: =COUNTIF(LeetCode!$A$5:$A$400,A21) -> 4 | L21: =COUNTIFS(LeetCode!$A$5:$A$400,A21,LeetCode!$H$5:$H$400,"Xong") -> 0 | P21: =IF(AND(M21="✓",N21="✓",O21="✓",L21>=K21),"Hoàn thành",IF(B21<TODAY(),"Trễ hạn",IF(OR(M21="✓",N21="✓",O21="✓",L21>0),"Đang học","Chưa bắt đầu"))) -> Chưa bắt đầu | Q21: 3 | R21: =IF(NhatKy!D21="","",NhatKy!D21)
A22: 18 | B22: =Dashboard!$B$4+A22-1 -> 46317 | C22: 2. CTDL & thuật toán kinh điển | D22: Danh sách liên kết (1) | E22: Đảo, gộp, Floyd phát hiện chu trình | F22: CTDL & thuật toán kinh điển | G22: struct ListNode* | H22: class ListNode | I22: 206, 21, 141, 142 | K22: =COUNTIF(LeetCode!$A$5:$A$400,A22) -> 4 | L22: =COUNTIFS(LeetCode!$A$5:$A$400,A22,LeetCode!$H$5:$H$400,"Xong") -> 0 | P22: =IF(AND(M22="✓",N22="✓",O22="✓",L22>=K22),"Hoàn thành",IF(B22<TODAY(),"Trễ hạn",IF(OR(M22="✓",N22="✓",O22="✓",L22>0),"Đang học","Chưa bắt đầu"))) -> Chưa bắt đầu | Q22: 3 | R22: =IF(NhatKy!D22="","",NhatKy!D22)
A23: 19 | B23: =Dashboard!$B$4+A23-1 -> 46318 | C23: 2. CTDL & thuật toán kinh điển | D23: Danh sách liên kết (2) | E23: Dummy node, hai con trỏ nhanh/chậm, cộng số lớn | F23: CTDL & thuật toán kinh điển | G23: con trỏ thô, dummy | H23: tham chiếu, dummy | I23: 19, 2, 143, 138 | K23: =COUNTIF(LeetCode!$A$5:$A$400,A23) -> 4 | L23: =COUNTIFS(LeetCode!$A$5:$A$400,A23,LeetCode!$H$5:$H$400,"Xong") -> 0 | P23: =IF(AND(M23="✓",N23="✓",O23="✓",L23>=K23),"Hoàn thành",IF(B23<TODAY(),"Trễ hạn",IF(OR(M23="✓",N23="✓",O23="✓",L23>0),"Đang học","Chưa bắt đầu"))) -> Chưa bắt đầu | Q23: 3 | R23: =IF(NhatKy!D23="","",NhatKy!D23)
... A32: 28 | B32: =Dashboard!$B$4+A32-1 -> 46327 | C32: 2. CTDL & thuật toán kinh điển | D32: Ôn tập tuần 4 | E32: DSU + hash + mảng ngẫu nhiên; làm lại bài sai tuần 2-4 | F32: CTDL & thuật toán kinh điển | G32: mt19937, rand | H32: ThreadLocalRandom | I32: 1319, 1722, 380 | K32: =COUNTIF(LeetCode!$A$5:$A$400,A32) -> 3 | L32: =COUNTIFS(LeetCode!$A$5:$A$400,A32,LeetCode!$H$5:$H$400,"Xong") -> 0 | P32: =IF(AND(M32="✓",N32="✓",O32="✓",L32>=K32),"Hoàn thành",IF(B32<TODAY(),"Trễ hạn",IF(OR(M32="✓",N32="✓",O32="✓",L32>0),"Đang học","Chưa bắt đầu"))) -> Chưa bắt đầu | Q32: 3 | R32: =IF(NhatKy!D32="","",NhatKy!D32)
A33: 29 | B33: =Dashboard!$B$4+A33-1 -> 46328 | C33: 3. RMQ & Segment Tree | D33: RMQ – Sparse Table (Slide T2-3) | E33: M[i][j] = chỉ số phần tử nhỏ nhất của đoạn bắt đầu tại j dài 2^i; M[0][j]=j; tiền xử lý O(N log N); truy vấn O(1) với k=floor(log2(j-i+1)) | F33: Slide T2-3 (RMQ) | G33: vector<vector<int>>, __lg() | H33: int[][], 31-Integer.numberOfLeadingZeros | I33: 1438, 1856, 2104, 907 | J33: Tự cài lại ví dụ slide: a={2,4,6,1,6,8,7,3,3,5,8,9,1,2,6,4}, RMQ(4,14)=12 | K33: =COUNTIF(LeetCode!$A$5:$A$400,A33) -> 4 | L33: =COUNTIFS(LeetCode!$A$5:$A$400,A33,LeetCode!$H$5:$H$400,"Xong") -> 0 | P33: =IF(AND(M33="✓",N33="✓",O33="✓",L33>=K33),"Hoàn thành",IF(B33<TODAY(),"Trễ hạn",IF(OR(M33="✓",N33="✓",O33="✓",L33>0),"Đang học","Chưa bắt đầu"))) -> Chưa bắt đầu | Q33: 3 | R33: =IF(NhatKy!D33="","",NhatKy!D33)
A34: 30 | B34: =Dashboard!$B$4+A34-1 -> 46329 | C34: 3. RMQ & Segment Tree | D34: RMQ nâng cao & binary lifting | E34: Sparse table cho gcd/max; binary lifting tìm tổ tiên thứ k | F34: Slide T2-3 (RMQ) | G34: bảng up[LOG][N] | H34: bảng up[LOG][N] | I34: 1483, 1157, 2398 | K34: =COUNTIF(LeetCode!$A$5:$A$400,A34) -> 3 | L34: =COUNTIFS(LeetCode!$A$5:$A$400,A34,LeetCode!$H$5:$H$400,"Xong") -> 0 | P34: =IF(AND(M34="✓",N34="✓",O34="✓",L34>=K34),"Hoàn thành",IF(B34<TODAY(),"Trễ hạn",IF(OR(M34="✓",N34="✓",O34="✓",L34>0),"Đang học","Chưa bắt đầu"))) -> Chưa bắt đầu | Q34: 3 | R34: =IF(NhatKy!D34="","",NhatKy!D34)
A35: 31 | B35: =Dashboard!$B$4+A35-1 -> 46330 | C35: 3. RMQ & Segment Tree | D35: Segment Tree (1): cấu trúc & GetMax (Slide T3) | E35: Nút id quản lý [L,R]; con trái 2id, phải 2id+1; maxVal[id]; ≤ 4n nút; mỗi tầng duyệt ≤ 4 nút → O(log n) | F35: Slide T3 (Segment Tree) | G35: vector<int> tree(4*n) | H35: int[] tree = new int[4*n] | I35: 307, 315 | J35: Tự viết thêm hàm Build O(n) (slide chưa có) | K35: =COUNTIF(LeetCode!$A$5:$A$400,A35) -> 2 | L35: =COUNTIFS(LeetCode!$A$5:$A$400,A35,LeetCode!$H$5:$H$400,"Xong") -> 0 | P35: =IF(AND(M35="✓",N35="✓",O35="✓",L35>=K35),"Hoàn thành",IF(B35<TODAY(),"Trễ hạn",IF(OR(M35="✓",N35="✓",O35="✓",L35>0),"Đang học","Chưa bắt đầu"))) -> Chưa bắt đầu | Q35: 3 | R35: =IF(NhatKy!D35="","",NhatKy!D35)
A36: 32 | B36: =Dashboard!$B$4+A36-1 -> 46331 | C36: 3. RMQ & Segment Tree | D36: Segment Tree (2): Update & ứng dụng | E36: UpdateFromNode xuống lá rồi tính lại max; O(log n); biến thể sum/min/gcd/đếm | F36: Slide T3 (Segment Tree) | G36: đệ quy 4 tham số | H36: đệ quy 4 tham số | I36: 699, 218, 1649 | K36: =COUNTIF(LeetCode!$A$5:$A$400,A36) -> 3 | L36: =COUNTIFS(LeetCode!$A$5:$A$400,A36,LeetCode!$H$5:$H$400,"Xong") -> 0 | P36: =IF(AND(M36="✓",N36="✓",O36="✓",L36>=K36),"Hoàn thành",IF(B36<TODAY(),"Trễ hạn",IF(OR(M36="✓",N36="✓",O36="✓",L36>0),"Đang học","Chưa bắt đầu"))) -> Chưa bắt đầu | Q36: 3 | R36: =IF(NhatKy!D36="","",NhatKy!D36)
A37: 33 | B37: =Dashboard!$B$4+A37-1 -> 46332 | C37: 3. RMQ & Segment Tree | D37: Lazy propagation & Fenwick Tree | E37: Cập nhật đoạn với lazy; BIT cho prefix sum; so sánh với segment tree | F37: Slide T3 (Segment Tree) | G37: vector<long long> bit | H37: long[] bit | I37: 493, 327, 2407 | K37: =COUNTIF(LeetCode!$A$5:$A$400,A37) -> 3 | L37: =COUNTIFS(LeetCode!$A$5:$A$400,A37,LeetCode!$H$5:$H$400,"Xong") -> 0 | P37: =IF(AND(M37="✓",N37="✓",O37="✓",L37>=K37),"Hoàn thành",IF(B37<TODAY(),"Trễ hạn",IF(OR(M37="✓",N37="✓",O37="✓",L37>0),"Đang học","Chưa bắt đầu"))) -> Chưa bắt đầu | Q37: 3 | R37: =IF(NhatKy!D37="","",NhatKy!D37)
A38: 34 | B38: =Dashboard!$B$4+A38-1 -> 46333 | C38: 3. RMQ & Segment Tree | D38: Ôn tập tuần 5 + template | E38: Hoàn thiện template Segment Tree generic (sum/min/max + lazy) cho C++ và Java | F38: Slide T3 (Segment Tree) | G38: template<typename T> | H38: generic class / IntBinaryOperator | I38: 2276, 2179 | J38: Lưu template vào thư viện cá nhân | K38: =COUNTIF(LeetCode!$A$5:$A$400,A38) -> 2 | L38: =COUNTIFS(LeetCode!$A$5:$A$400,A38,LeetCode!$H$5:$H$400,"Xong") -> 0 | P38: =IF(AND(M38="✓",N38="✓",O38="✓",L38>=K38),"Hoàn thành",IF(B38<TODAY(),"Trễ hạn",IF(OR(M38="✓",N38="✓",O38="✓",L38>0),"Đang học","Chưa bắt đầu"))) -> Chưa bắt đầu | Q38: 3 | R38: =IF(NhatKy!D38="","",NhatKy!D38)
A39: 35 | B39: =Dashboard!$B$4+A39-1 -> 46334 | C39: 4. Quay lui & Nhánh cận | D39: Quay lui: sơ đồ chung (Slide T4) | E39: try(k): với v ∈ A_k: check(v,k) → X_k=v → [cập nhật D] → k=n ? ghi nhận : try(k+1) → [khôi phục D] | F39: Slide T4 (Chương 3) | G39: vector<bool> used, push_back/pop_back | H39: boolean[] used, list.remove(size-1) | I39: 78, 90, 46, 47 | K39: =COUNTIF(LeetCode!$A$5:$A$400,A39) -> 4 | L39: =COUNTIFS(LeetCode!$A$5:$A$400,A39,LeetCode!$H$5:$H$400,"Xong") -> 0 | P39: =IF(AND(M39="✓",N39="✓",O39="✓",L39>=K39),"Hoàn thành",IF(B39<TODAY(),"Trễ hạn",IF(OR(M39="✓",N39="✓",O39="✓",L39>0),"Đang học","Chưa bắt đầu"))) -> Chưa bắt đầu | Q39: 3 | R39: =IF(NhatKy!D39="","",NhatKy!D39)
A40: 36 | B40: =Dashboard!$B$4+A40-1 -> 46335 | C40: 4. Quay lui & Nhánh cận | D40: Tổ hợp, hoán vị & loại trùng | E40: Sắp xếp + bỏ qua phần tử trùng; cận tổng; start index | F40: Slide T4 (Chương 3) | G40: sort + continue | H40: Arrays.sort + continue | I40: 77, 39, 40, 216 | K40: =COUNTIF(LeetCode!$A$5:$A$400,A40) -> 4 | L40: =COUNTIFS(LeetCode!$A$5:$A$400,A40,LeetCode!$H$5:$H$400,"Xong") -> 0 | P40: =IF(AND(M40="✓",N40="✓",O40="✓",L40>=K40),"Hoàn thành",IF(B40<TODAY(),"Trễ hạn",IF(OR(M40="✓",N40="✓",O40="✓",L40>0),"Đang học","Chưa bắt đầu"))) -> Chưa bắt đầu | Q40: 3 | R40: =IF(NhatKy!D40="","",NhatKy!D40)
A41: 37 | B41: =Dashboard!$B$4+A41-1 -> 46336 | C41: 4. Quay lui & Nhánh cận | D41: Quay lui có ràng buộc | E41: Cắt tỉa sớm; thử trên lưới; chia xâu | F41: Slide T4 (Chương 3) | G41: string, vector<string> | H41: StringBuilder, List<String> | I41: 17, 22, 79, 131 | K41: =COUNTIF(LeetCode!$A$5:$A$400,A41) -> 4 | L41: =COUNTIFS(LeetCode!$A$5:$A$400,A41,LeetCode!$H$5:$H$400,"Xong") -> 0 | P41: =IF(AND(M41="✓",N41="✓",O41="✓",L41>=K41),"Hoàn thành",IF(B41<TODAY(),"Trễ hạn",IF(OR(M41="✓",N41="✓",O41="✓",L41>0),"Đang học","Chưa bắt đầu"))) -> Chưa bắt đầu | Q41: 3 | R41: =IF(NhatKy!D41="","",NhatKy!D41)
A42: 38 | B42: =Dashboard!$B$4+A42-1 -> 46337 | C42: 4. Quay lui & Nhánh cận | D42: N-Queens, Sudoku, IP | E42: Mảng đánh dấu cột/đường chéo; bitmask; thứ tự chọn ô | F42: Slide T4 (Chương 3) | G42: bitset / mảng bool | H42: boolean[] | I42: 51, 52, 37, 93 | K42: =COUNTIF(LeetCode!$A$5:$A$400,A42) -> 4 | L42: =COUNTIFS(LeetCode!$A$5:$A$400,A42,LeetCode!$H$5:$H$400,"Xong") -> 0 | P42: =IF(AND(M42="✓",N42="✓",O42="✓",L42>=K42),"Hoàn thành",IF(B42<TODAY(),"Trễ hạn",IF(OR(M42="✓",N42="✓",O42="✓",L42>0),"Đang học","Chưa bắt đầu"))) -> Chưa bắt đầu | Q42: 3 | R42: =IF(NhatKy!D42="","",NhatKy!D42)
A43: 39 | B43: =Dashboard!$B$4+A43-1 -> 46338 | C43: 4. Quay lui & Nhánh cận | D43: Ôn tập tuần 6: chia tập (bin packing) | E43: Sắp xếp giảm dần + cắt tỉa; thử đặt vào từng "thùng" | F43: Slide T4 (Chương 3) | G43: sort greater | H43: Arrays.sort + đảo | I43: 698, 473, 2305, 1239 | K43: =COUNTIF(LeetCode!$A$5:$A$400,A43) -> 4 | L43: =COUNTIFS(LeetCode!$A$5:$A$400,A43,LeetCode!$H$5:$H$400,"Xong") -> 0 | P43: =IF(AND(M43="✓",N43="✓",O43="✓",L43>=K43),"Hoàn thành",IF(B43<TODAY(),"Trễ hạn",IF(OR(M43="✓",N43="✓",O43="✓",L43>0),"Đang học","Chưa bắt đầu"))) -> Chưa bắt đầu | Q43: 3 | R43: =IF(NhatKy!D43="","",NhatKy!D43)
A44: 40 | B44: =Dashboard!$B$4+A44-1 -> 46339 | C44: 4. Quay lui & Nhánh cận | D44: Nhánh cận (Slide T4): sơ đồ chung | E44: Kỷ lục f*; cận dưới g(X1..Xk); chỉ gọi try(k+1) nếu g < f*; thứ tự thử tốt → tìm kỷ lục sớm | F44: Slide T4 (Chương 3) | G44: biến toàn cục best | H44: static int best | I44: 847, 943, 1723 | K44: =COUNTIF(LeetCode!$A$5:$A$400,A44) -> 3 | L44: =COUNTIFS(LeetCode!$A$5:$A$400,A44,LeetCode!$H$5:$H$400,"Xong") -> 0 | P44: =IF(AND(M44="✓",N44="✓",O44="✓",L44>=K44),"Hoàn thành",IF(B44<TODAY(),"Trễ hạn",IF(OR(M44="✓",N44="✓",O44="✓",L44>0),"Đang học","Chưa bắt đầu"))) -> Chưa bắt đầu | Q44: 3 | R44: =IF(NhatKy!D44="","",NhatKy!D44)
A45: 41 | B45: =Dashboard!$B$4+A45-1 -> 46340 | C45: 4. Quay lui & Nhánh cận | D45: CBUS – lộ trình xe buýt đón trả khách (Slide T4) | E45: X1..X2n hoán vị 1..2n; khách i đón tại i, trả tại i+n; load ≤ K; cận f + Cmin·(2n+1−k); updateBest cộng d(X2n,0) | F45: Slide T4 (Chương 3) | G45: visited[], load, f, best | H45: visited[], load, f, best | I45: 1359, 1986, 1879 | J45: Cài đúng theo slide, tự sinh test nhỏ để so với vét cạn | K45: =COUNTIF(LeetCode!$A$5:$A$400,A45) -> 3 | L45: =COUNTIFS(LeetCode!$A$5:$A$400,A45,LeetCode!$H$5:$H$400,"Xong") -> 0 | P45: =IF(AND(M45="✓",N45="✓",O45="✓",L45>=K45),"Hoàn thành",IF(B45<TODAY(),"Trễ hạn",IF(OR(M45="✓",N45="✓",O45="✓",L45>0),"Đang học","Chưa bắt đầu"))) -> Chưa bắt đầu | Q45: 3 | R45: =IF(NhatKy!D45="","",NhatKy!D45)
A46: 42 | B46: =Dashboard!$B$4+A46-1 -> 46341 | C46: 4. Quay lui & Nhánh cận | D46: Cắt vật liệu 2D – bin packing 2D (Slide T4) | E46: Mỗi miếng (x,y,o); mark[i][j]; check/doMark/undo; xoay 90° | F46: Slide T4 (Chương 3) | G46: bool mark[H][W] | H46: boolean[][] mark | I46: 391, 223, 850 | J46: Slide: check dùng h[k],w[k] thay vì hk,wk khi xoay → tự sửa khi cài | K46: =COUNTIF(LeetCode!$A$5:$A$400,A46) -> 3 | L46: =COUNTIFS(LeetCode!$A$5:$A$400,A46,LeetCode!$H$5:$H$400,"Xong") -> 0 | P46: =IF(AND(M46="✓",N46="✓",O46="✓",L46>=K46),"Hoàn thành",IF(B46<TODAY(),"Trễ hạn",IF(OR(M46="✓",N46="✓",O46="✓",L46>0),"Đang học","Chưa bắt đầu"))) -> Chưa bắt đầu | Q46: 3 | R46: =IF(NhatKy!D46="","",NhatKy!D46)
A47: 43 | B47: =Dashboard!$B$4+A47-1 -> 46342 | C47: 4. Quay lui & Nhánh cận | D47: CVRP – xe tải giao hàng (Slide T5) | E47: Nhiều xe, tải trọng Q, mỗi khách thăm 1 lần; tối thiểu tổng quãng đường; cận dưới + kỷ lục khởi tạo bằng tham lam | F47: Slide T5 (Chương 3) | G47: vector<vector<int>> dist | H47: int[][] dist | I47: 1125, 1595, 2172 | J47: Đối chiếu nội dung slide tuần 5; tự sinh test nhỏ để kiểm tra | K47: =COUNTIF(LeetCode!$A$5:$A$400,A47) -> 3 | L47: =COUNTIFS(LeetCode!$A$5:$A$400,A47,LeetCode!$H$5:$H$400,"Xong") -> 0 | P47: =IF(AND(M47="✓",N47="✓",O47="✓",L47>=K47),"Hoàn thành",IF(B47<TODAY(),"Trễ hạn",IF(OR(M47="✓",N47="✓",O47="✓",L47>0),"Đang học","Chưa bắt đầu"))) -> Chưa bắt đầu | Q47: 3 | R47: =IF(NhatKy!D47="","",NhatKy!D47)
A48: 44 | B48: =Dashboard!$B$4+A48-1 -> 46343 | C48: 4. Quay lui & Nhánh cận | D48: Ôn tập tuần 7: nhánh cận + bitmask | E48: So sánh quay lui thuần vs nhánh cận vs bitmask DP trên cùng một bài | F48: Slide T5 (Chương 3) | G48: __builtin_popcount | H48: Integer.bitCount | I48: 2597, 1255 | K48: =COUNTIF(LeetCode!$A$5:$A$400,A48) -> 2 | L48: =COUNTIFS(LeetCode!$A$5:$A$400,A48,LeetCode!$H$5:$H$400,"Xong") -> 0 | P48: =IF(AND(M48="✓",N48="✓",O48="✓",L48>=K48),"Hoàn thành",IF(B48<TODAY(),"Trễ hạn",IF(OR(M48="✓",N48="✓",O48="✓",L48>0),"Đang học","Chưa bắt đầu"))) -> Chưa bắt đầu | Q48: 3 | R48: =IF(NhatKy!D48="","",NhatKy!D48)
A49: 45 | B49: =Dashboard!$B$4+A49-1 -> 46344 | C49: 5. Tham lam | D49: Tham lam: nguyên lý & exchange argument (Slide T6) | E49: Lựa chọn cục bộ tối ưu; chứng minh bằng đổi chỗ; tìm phản ví dụ | F49: Slide T6 (Chương 4: Tham lam) | G49: sort + vòng lặp tham lam | H49: Arrays.sort | I49: 455, 860, 605, 1005 | K49: =COUNTIF(LeetCode!$A$5:$A$400,A49) -> 4 | L49: =COUNTIFS(LeetCode!$A$5:$A$400,A49,LeetCode!$H$5:$H$400,"Xong") -> 0 | P49: =IF(AND(M49="✓",N49="✓",O49="✓",L49>=K49),"Hoàn thành",IF(B49<TODAY(),"Trễ hạn",IF(OR(M49="✓",N49="✓",O49="✓",L49>0),"Đang học","Chưa bắt đầu"))) -> Chưa bắt đầu | Q49: 3 | R49: =IF(NhatKy!D49="","",NhatKy!D49)
...

Sheet LeetCode
A1: DANH SÁCH BÀI LEETCODE THEO LỘ TRÌNH (338 bài)
A2: Cột Link chứa URL tìm kiếm LeetCode theo tên bài. Ô nền vàng = bạn nhập. Chu kỳ ôn lấy từ Dashboard!B5:B7.
A4: Ngày | B4: Giai đoạn | C4: Chủ đề | D4: # | E4: Tên bài | F4: Độ khó | G4: Link | H4: Trạng thái | I4: C++ ✓ | J4: Java ✓ | K4: Ngày giải | L4: Số lần thử | M4: Ghi chú / ý tưởng / độ phức tạp | N4: Ôn lần 1 | O4: Ôn lần 2 | P4: Ôn lần 3 | Q4: Lần ôn kế tiếp
A5: 1 | B5: 1. Nền tảng | C5: Môi trường, I/O nhanh, độ phức tạp Big-O | D5: 1 | E5: Two Sum | F5: Easy | G5: https://leetcode.com/problemset/?search=Two%20Sum | H5: Xong | I5: ✓ | K5: 46300 | L5: 1 | M5: unordered_map / O(n) | N5: =IF($K5="","",$K5+Dashboard!$B$5) -> 46303 | O5: =IF($K5="","",$K5+Dashboard!$B$6) -> 46307 | P5: =IF($K5="","",$K5+Dashboard!$B$7) -> 46314 | Q5: =IF($K5="","",IF(TODAY()<=N5,N5,IF(TODAY()<=O5,O5,IF(TODAY()<=P5,P5,"Đã ôn đủ")))) -> 46303
A6: 1 | B6: 1. Nền tảng | C6: Môi trường, I/O nhanh, độ phức tạp Big-O | D6: 412 | E6: Fizz Buzz | F6: Easy | G6: https://leetcode.com/problemset/?search=Fizz%20Buzz | H6: Chưa làm | N6: =IF($K6="","",$K6+Dashboard!$B$5) | O6: =IF($K6="","",$K6+Dashboard!$B$6) | P6: =IF($K6="","",$K6+Dashboard!$B$7) | Q6: =IF($K6="","",IF(TODAY()<=N6,N6,IF(TODAY()<=O6,O6,IF(TODAY()<=P6,P6,"Đã ôn đủ"))))
A7: 1 | B7: 1. Nền tảng | C7: Môi trường, I/O nhanh, độ phức tạp Big-O | D7: 217 | E7: Contains Duplicate | F7: Easy | G7: https://leetcode.com/problemset/?search=Contains%20Duplicate | H7: Chưa làm | N7: =IF($K7="","",$K7+Dashboard!$B$5) | O7: =IF($K7="","",$K7+Dashboard!$B$6) | P7: =IF($K7="","",$K7+Dashboard!$B$7) | Q7: =IF($K7="","",IF(TODAY()<=N7,N7,IF(TODAY()<=O7,O7,IF(TODAY()<=P7,P7,"Đã ôn đủ"))))
A8: 2 | B8: 1. Nền tảng | C8: Mảng 1 chiều & kỹ thuật in-place | D8: 26 | E8: Remove Duplicates from Sorted Array | F8: Easy | G8: https://leetcode.com/problemset/?search=Remove%20Duplicates%20from%20Sorted%20Array | H8: Chưa làm | N8: =IF($K8="","",$K8+Dashboard!$B$5) | O8: =IF($K8="","",$K8+Dashboard!$B$6) | P8: =IF($K8="","",$K8+Dashboard!$B$7) | Q8: =IF($K8="","",IF(TODAY()<=N8,N8,IF(TODAY()<=O8,O8,IF(TODAY()<=P8,P8,"Đã ôn đủ"))))
A9: 2 | B9: 1. Nền tảng | C9: Mảng 1 chiều & kỹ thuật in-place | D9: 27 | E9: Remove Element | F9: Easy | G9: https://leetcode.com/problemset/?search=Remove%20Element | H9: Chưa làm | N9: =IF($K9="","",$K9+Dashboard!$B$5) | O9: =IF($K9="","",$K9+Dashboard!$B$6) | P9: =IF($K9="","",$K9+Dashboard!$B$7) | Q9: =IF($K9="","",IF(TODAY()<=N9,N9,IF(TODAY()<=O9,O9,IF(TODAY()<=P9,P9,"Đã ôn đủ"))))
A10: 2 | B10: 1. Nền tảng | C10: Mảng 1 chiều & kỹ thuật in-place | D10: 88 | E10: Merge Sorted Array | F10: Easy | G10: https://leetcode.com/problemset/?search=Merge%20Sorted%20Array | H10: Chưa làm | N10: =IF($K10="","",$K10+Dashboard!$B$5) | O10: =IF($K10="","",$K10+Dashboard!$B$6) | P10: =IF($K10="","",$K10+Dashboard!$B$7) | Q10: =IF($K10="","",IF(TODAY()<=N10,N10,IF(TODAY()<=O10,O10,IF(TODAY()<=P10,P10,"Đã ôn đủ"))))
A11: 2 | B11: 1. Nền tảng | C11: Mảng 1 chiều & kỹ thuật in-place | D11: 283 | E11: Move Zeroes | F11: Easy | G11: https://leetcode.com/problemset/?search=Move%20Zeroes | H11: Chưa làm | N11: =IF($K11="","",$K11+Dashboard!$B$5) | O11: =IF($K11="","",$K11+Dashboard!$B$6) | P11: =IF($K11="","",$K11+Dashboard!$B$7) | Q11: =IF($K11="","",IF(TODAY()<=N11,N11,IF(TODAY()<=O11,O11,IF(TODAY()<=P11,P11,"Đã ôn đủ"))))
A12: 3 | B12: 1. Nền tảng | C12: Xâu ký tự cơ bản | D12: 344 | E12: Reverse String | F12: Easy | G12: https://leetcode.com/problemset/?search=Reverse%20String | H12: Chưa làm | N12: =IF($K12="","",$K12+Dashboard!$B$5) | O12: =IF($K12="","",$K12+Dashboard!$B$6) | P12: =IF($K12="","",$K12+Dashboard!$B$7) | Q12: =IF($K12="","",IF(TODAY()<=N12,N12,IF(TODAY()<=O12,O12,IF(TODAY()<=P12,P12,"Đã ôn đủ"))))
A13: 3 | B13: 1. Nền tảng | C13: Xâu ký tự cơ bản | D13: 125 | E13: Valid Palindrome | F13: Easy | G13: https://leetcode.com/problemset/?search=Valid%20Palindrome | H13: Chưa làm | N13: =IF($K13="","",$K13+Dashboard!$B$5) | O13: =IF($K13="","",$K13+Dashboard!$B$6) | P13: =IF($K13="","",$K13+Dashboard!$B$7) | Q13: =IF($K13="","",IF(TODAY()<=N13,N13,IF(TODAY()<=O13,O13,IF(TODAY()<=P13,P13,"Đã ôn đủ"))))
A14: 3 | B14: 1. Nền tảng | C14: Xâu ký tự cơ bản | D14: 242 | E14: Valid Anagram | F14: Easy | G14: https://leetcode.com/problemset/?search=Valid%20Anagram | H14: Chưa làm | N14: =IF($K14="","",$K14+Dashboard!$B$5) | O14: =IF($K14="","",$K14+Dashboard!$B$6) | P14: =IF($K14="","",$K14+Dashboard!$B$7) | Q14: =IF($K14="","",IF(TODAY()<=N14,N14,IF(TODAY()<=O14,O14,IF(TODAY()<=P14,P14,"Đã ôn đủ"))))
A15: 3 | B15: 1. Nền tảng | C15: Xâu ký tự cơ bản | D15: 14 | E15: Longest Common Prefix | F15: Easy | G15: https://leetcode.com/problemset/?search=Longest%20Common%20Prefix | H15: Chưa làm | N15: =IF($K15="","",$K15+Dashboard!$B$5) | O15: =IF($K15="","",$K15+Dashboard!$B$6) | P15: =IF($K15="","",$K15+Dashboard!$B$7) | Q15: =IF($K15="","",IF(TODAY()<=N15,N15,IF(TODAY()<=O15,O15,IF(TODAY()<=P15,P15,"Đã ôn đủ"))))
A16: 4 | B16: 1. Nền tảng | C16: Số học cơ bản & tràn số | D16: 9 | E16: Palindrome Number | F16: Easy | G16: https://leetcode.com/problemset/?search=Palindrome%20Number | H16: Chưa làm | N16: =IF($K16="","",$K16+Dashboard!$B$5) | O16: =IF($K16="","",$K16+Dashboard!$B$6) | P16: =IF($K16="","",$K16+Dashboard!$B$7) | Q16: =IF($K16="","",IF(TODAY()<=N16,N16,IF(TODAY()<=O16,O16,IF(TODAY()<=P16,P16,"Đã ôn đủ"))))
A17: 4 | B17: 1. Nền tảng | C17: Số học cơ bản & tràn số | D17: 13 | E17: Roman to Integer | F17: Easy | G17: https://leetcode.com/problemset/?search=Roman%20to%20Integer | H17: Chưa làm | N17: =IF($K17="","",$K17+Dashboard!$B$5) | O17: =IF($K17="","",$K17+Dashboard!$B$6) | P17: =IF($K17="","",$K17+Dashboard!$B$7) | Q17: =IF($K17="","",IF(TODAY()<=N17,N17,IF(TODAY()<=O17,O17,IF(TODAY()<=P17,P17,"Đã ôn đủ"))))
... A342: 98 | B342: 12. NP-đầy đủ & Tổng ôn | C342: NP-đầy đủ (Slide T15) | D342: 996 | E342: Number of Squareful Arrays | F342: Hard | G342: https://leetcode.com/problemset/?search=Number%20of%20Squareful%20Arrays | H342: Chưa làm | N342: =IF($K342="","",$K342+Dashboard!$B$5) | O342: =IF($K342="","",$K342+Dashboard!$B$6) | P342: =IF($K342="","",$K342+Dashboard!$B$7) | Q342: =IF($K342="","",IF(TODAY()<=N342,N342,IF(TODAY()<=O342,O342,IF(TODAY()<=P342,P342,"Đã ôn đủ"))))

Sheet NhatKy
A1: NHẬT KÝ HỌC TẬP HẰNG NGÀY
A2: Nhập Giờ học thực tế, Tự đánh giá, Điều đã học, Vướng mắc. Số bài giải và chuỗi ngày học tự tính.
A4: Ngày # | B4: Ngày | C4: Tuần | D4: Giờ học thực tế | E4: Giờ KH | F4: Số bài giải | G4: Tự đánh giá (1-5) | H4: Điều đã học | I4: Vướng mắc / việc cần làm lại | J4: Chuỗi ngày học
A5: 1 | B5: =Dashboard!$B$4+A5-1 -> 46300 | C5: =INT((A5-1)/7)+1 -> 1 | E5: =Roadmap!Q5 -> 3 | F5: =COUNTIF(LeetCode!$K$5:$K$400,B5) -> 1 | J5: =IF(D5>0,1,0) -> 0
A6: 2 | B6: =Dashboard!$B$4+A6-1 -> 46301 | C6: =INT((A6-1)/7)+1 -> 1 | E6: =Roadmap!Q6 -> 3 | F6: =COUNTIF(LeetCode!$K$5:$K$400,B6) -> 0 | J6: =IF(D6>0,J5+1,0) -> 0
A7: 3 | B7: =Dashboard!$B$4+A7-1 -> 46302 | C7: =INT((A7-1)/7)+1 -> 1 | E7: =Roadmap!Q7 -> 3 | F7: =COUNTIF(LeetCode!$K$5:$K$400,B7) -> 0 | J7: =IF(D7>0,J6+1,0) -> 0
A8: 4 | B8: =Dashboard!$B$4+A8-1 -> 46303 | C8: =INT((A8-1)/7)+1 -> 1 | E8: =Roadmap!Q8 -> 3 | F8: =COUNTIF(LeetCode!$K$5:$K$400,B8) -> 0 | J8: =IF(D8>0,J7+1,0) -> 0
A9: 5 | B9: =Dashboard!$B$4+A9-1 -> 46304 | C9: =INT((A9-1)/7)+1 -> 1 | E9: =Roadmap!Q9 -> 3 | F9: =COUNTIF(LeetCode!$K$5:$K$400,B9) -> 0 | J9: =IF(D9>0,J8+1,0) -> 0
A10: 6 | B10: =Dashboard!$B$4+A10-1 -> 46305 | C10: =INT((A10-1)/7)+1 -> 1 | E10: =Roadmap!Q10 -> 3 | F10: =COUNTIF(LeetCode!$K$5:$K$400,B10) -> 0 | J10: =IF(D10>0,J9+1,0) -> 0
A11: 7 | B11: =Dashboard!$B$4+A11-1 -> 46306 | C11: =INT((A11-1)/7)+1 -> 1 | E11: =Roadmap!Q11 -> 3 | F11: =COUNTIF(LeetCode!$K$5:$K$400,B11) -> 0 | J11: =IF(D11>0,J10+1,0) -> 0
A12: 8 | B12: =Dashboard!$B$4+A12-1 -> 46307 | C12: =INT((A12-1)/7)+1 -> 2 | E12: =Roadmap!Q12 -> 3 | F12: =COUNTIF(LeetCode!$K$5:$K$400,B12) -> 0 | J12: =IF(D12>0,J11+1,0) -> 0
A13: 9 | B13: =Dashboard!$B$4+A13-1 -> 46308 | C13: =INT((A13-1)/7)+1 -> 2 | E13: =Roadmap!Q13 -> 3 | F13: =COUNTIF(LeetCode!$K$5:$K$400,B13) -> 0 | J13: =IF(D13>0,J12+1,0) -> 0
A14: 10 | B14: =Dashboard!$B$4+A14-1 -> 46309 | C14: =INT((A14-1)/7)+1 -> 2 | E14: =Roadmap!Q14 -> 3 | F14: =COUNTIF(LeetCode!$K$5:$K$400,B14) -> 0 | J14: =IF(D14>0,J13+1,0) -> 0
A15: 11 | B15: =Dashboard!$B$4+A15-1 -> 46310 | C15: =INT((A15-1)/7)+1 -> 2 | E15: =Roadmap!Q15 -> 3 | F15: =COUNTIF(LeetCode!$K$5:$K$400,B15) -> 0 | J15: =IF(D15>0,J14+1,0) -> 0
A16: 12 | B16: =Dashboard!$B$4+A16-1 -> 46311 | C16: =INT((A16-1)/7)+1 -> 2 | E16: =Roadmap!Q16 -> 3 | F16: =COUNTIF(LeetCode!$K$5:$K$400,B16) -> 0 | J16: =IF(D16>0,J15+1,0) -> 0
A17: 13 | B17: =Dashboard!$B$4+A17-1 -> 46312 | C17: =INT((A17-1)/7)+1 -> 2 | E17: =Roadmap!Q17 -> 3 | F17: =COUNTIF(LeetCode!$K$5:$K$400,B17) -> 0 | J17: =IF(D17>0,J16+1,0) -> 0
... A104: 100 | B104: =Dashboard!$B$4+A104-1 -> 46399 | C104: =INT((A104-1)/7)+1 -> 15 | E104: =Roadmap!Q104 -> 4 | F104: =COUNTIF(LeetCode!$K$5:$K$400,B104) -> 0 | J104: =IF(D104>0,J103+1,0) -> 0

Sheet Slide
A1: CHECKLIST NỘI DUNG SLIDE (TUẦN 1 – 15)
A2: Mục đã nắm = đủ 4 dấu ✓. Các mục chưa có chi tiết là gợi ý dựa trên tên file slide, hãy đối chiếu và sửa theo nội dung thật.
A4: Tuần | B4: Chương | C4: Chủ đề / thuật toán | D4: Ngày roadmap | E4: Trạng thái ngày học | F4: Ý chính / độ phức tạp | G4: Lưu ý khi cài đặt (sai sót / chi tiết trong slide) | H4: Hiểu lý thuyết ✓ | I4: Cài C++ ✓ | J4: Cài Java ✓ | K4: Tự giải thích lại ✓ | L4: Ghi chú
A5: T1 | B5: Ch.1 | C5: Giới thiệu môn học & thư viện hỗ trợ | D5: 1 | E5: =INDEX(Roadmap!$P$5:$P$104,D5) -> Đang học | F5: Ôn thư viện chuẩn C++ (STL) và Java (Collections) – xem sheet Cpp_vs_Java | G5: Gợi ý theo tên file; chưa đối chiếu nội dung slide
A6: T2-3 | B6: Ch.2 | C6: RMQ – cách trực tiếp | D6: 29 | E6: =INDEX(Roadmap!$P$5:$P$104,D6) -> Chưa bắt đầu | F6: Duyệt a[i..j] mỗi truy vấn: O(j−i); K truy vấn → O(K·N) | G6: Slide 6 có lỗi gõ "min = a[k];, min_idx"
A7: T2-3 | B7: Ch.2 | C7: RMQ – tiền xử lý Sparse Table | D7: 29 | E7: =INDEX(Roadmap!$P$5:$P$104,D7) -> Chưa bắt đầu | F7: M[0][j]=j; M[i][j] chọn min của M[i−1][j] và M[i−1][j+2^(i−1)]; O(N log N) thời gian và bộ nhớ | G7: Slide đổi vai trò i/j giữa các trang (tầng / vị trí) – thống nhất ký hiệu khi cài
A8: T2-3 | B8: Ch.2 | C8: RMQ – truy vấn O(1) | D8: 29 | E8: =INDEX(Roadmap!$P$5:$P$104,D8) -> Chưa bắt đầu | F8: k=⌊log2(j−i+1)⌋; so M[k][i] với M[k][j−2^k+1] (hai khối chồng nhau); ví dụ RMQ(4,14)=12 | G8: Thống nhất cách xử lý khi hai giá trị bằng nhau (chọn chỉ số nào)
A9: T2-3 | B9: Ch.2 | C9: Segment Tree – cấu trúc | D9: 31 | E9: =INDEX(Roadmap!$P$5:$P$104,D9) -> Chưa bắt đầu | F9: Cây nhị phân đầy đủ; nút id quản lý [L,R]; con 2id và 2id+1; lưu maxVal[id]; ≤ 4n nút | G9: Mảng kích thước 4n, chỉ số nút bắt đầu từ 1
A10: T2-3 | B10: Ch.2 | C10: Segment Tree – GetMax(i,j) | D10: 31 | E10: =INDEX(Roadmap!$P$5:$P$104,D10) -> Chưa bắt đầu | F10: Rời nhau → −∞; nằm trọn → maxVal; còn lại gộp hai con; mỗi tầng ≤ 4 nút → O(log n)
A11: T2-3 | B11: Ch.2 | C11: Segment Tree – Update(i,v) | D11: 32 | E11: =INDEX(Roadmap!$P$5:$P$104,D11) -> Chưa bắt đầu | F11: Xuống lá, cập nhật rồi tính lại maxVal[id]=max(con); O(log n) | G11: Slide chưa có hàm Build ban đầu (O(n)) – tự viết
A12: T4 | B12: Ch.3 | C12: Sơ đồ chung quay lui (liệt kê) | D12: 35 | E12: =INDEX(Roadmap!$P$5:$P$104,D12) -> Chưa bắt đầu | F12: try(k): for v in A_k: check → gán X_k → [cập nhật D] → try(k+1) → [khôi phục D]
A13: T4 | B13: Ch.3 | C13: Sơ đồ nhánh cận (tìm min) | D13: 40 | E13: =INDEX(Roadmap!$P$5:$P$104,D13) -> Chưa bắt đầu | F13: Kỷ lục f*; cận dưới g(X1..Xk); chỉ gọi try(k+1) nếu g < f*
A14: T4 | B14: Ch.3 | C14: CBUS – xe buýt đón trả khách | D14: 41 | E14: =INDEX(Roadmap!$P$5:$P$104,D14) -> Chưa bắt đầu | F14: X1..X2n là hoán vị; visited[]; load ≤ K; cận f + Cmin·(2n+1−k); updateBest cộng d(X2n,0) | G14: Cmin là khoảng cách nhỏ nhất giữa mọi cặp điểm; trả khách chỉ khi đã đón
A15: T4 | B15: Ch.3 | C15: Cắt vật liệu 2D (bin packing 2D) | D15: 42 | E15: =INDEX(Roadmap!$P$5:$P$104,D15) -> Chưa bắt đầu | F15: Biến (x,y,o) mỗi miếng; mark[i][j]; check / doMark / undo; xoay 90° | G15: Slide: check dùng h[k], w[k] thay vì hk, wk khi xoay; doMark gọi và định nghĩa khác thứ tự tham số; i/j ứng với hàng/cột cần chuẩn hoá
A16: T5 | B16: Ch.3 | C16: CVRP – xe tải giao hàng | D16: 43 | E16: =INDEX(Roadmap!$P$5:$P$104,D16) -> Chưa bắt đầu | F16: Nhiều xe, tải trọng; nhánh cận (đối chiếu slide) | G16: Gợi ý theo tên file; chưa đối chiếu nội dung slide
A17: T6 | B17: Ch.4 | C17: Tham lam | D17: 45 | E17: =INDEX(Roadmap!$P$5:$P$104,D17) -> Chưa bắt đầu | F17: Tiêu chí chọn, chứng minh tính đúng (đối chiếu slide) | G17: Gợi ý theo tên file
A18: T7 | B18: Ch.4 | C18: Chia để trị | D18: 52 | E18: =INDEX(Roadmap!$P$5:$P$104,D18) -> Chưa bắt đầu | F18: Divide–Conquer–Combine, Master theorem (đối chiếu slide) | G18: Gợi ý theo tên file
A19: T8-9 | B19: Ch.4 | C19: Quy hoạch động | D19: 57 | E19: =INDEX(Roadmap!$P$5:$P$104,D19) -> Chưa bắt đầu | F19: Bài toán con, truy hồi, bảng, tối ưu bộ nhớ (đối chiếu slide) | G19: Gợi ý theo tên file
A20: T10 | B20: Ch.5 | C20: DFS và ứng dụng | D20: 74 | E20: =INDEX(Roadmap!$P$5:$P$104,D20) -> Chưa bắt đầu | F20: DFS, thành phần liên thông, tôpô… (đối chiếu slide) | G20: Gợi ý theo tên file
A21: T11 | B21: Ch.5 | C21: Đường đi dài nhất trên cây | D21: 82 | E21: =INDEX(Roadmap!$P$5:$P$104,D21) -> Chưa bắt đầu | F21: DFS(s) → x xa nhất → DFS(x) → y; O(V+E)
A22: T11 | B22: Ch.5 | C22: Tổng đường đi trên cây (rerooting) | D22: 83 | E22: =INDEX(Roadmap!$P$5:$P$104,D22) -> Chưa bắt đầu | F22: Pha 1: d(u)+=d(v)+N(v)·w, N(u)+=N(v). Pha 2: f(v)=F+d(v)+w·(n−N(v)) với F=f(u)−(d(v)+w·N(v)); O(V+E) | G22: Slide 10 ghi d(u)=d(u)+N(v)*d(v) (bản rút gọn); công thức đầy đủ ở slide 11
A23: T12 | B23: Ch.5 | C23: Luồng cực đại (Max Flow) | D23: 87 | E23: =INDEX(Roadmap!$P$5:$P$104,D23) -> Chưa bắt đầu | F23: Đồ thị thặng dư, đường tăng luồng (đối chiếu slide) | G23: Gợi ý theo tên file
A24: T12 | B24: Ch.5 | C24: Ghép cặp cực đại (Max Matching) | D24: 88 | E24: =INDEX(Roadmap!$P$5:$P$104,D24) -> Chưa bắt đầu | F24: Đồ thị hai phía, đường tăng (đối chiếu slide) | G24: Gợi ý theo tên file
A25: T12 | B25: Ch.5 | C25: Thuật toán Hungarian | D25: 89 | E25: =INDEX(Roadmap!$P$5:$P$104,D25) -> Chưa bắt đầu | F25: Bài toán phân công O(n³) (đối chiếu slide) | G25: Gợi ý theo tên file
A26: T13 | B26: Ch.6 | C26: Hình học tính toán | D26: 91 | E26: =INDEX(Roadmap!$P$5:$P$104,D26) -> Chưa bắt đầu | F26: Tích có hướng, bao lồi, giao đoạn thẳng (đối chiếu slide) | G26: Gợi ý theo tên file
A27: T14 | B27: Ch.7 | C27: Thuật toán xâu | D27: 94 | E27: =INDEX(Roadmap!$P$5:$P$104,D27) -> Chưa bắt đầu | F27: KMP, hashing, Trie… (đối chiếu slide) | G27: Gợi ý theo tên file
A28: T15 | B28: Ch.8 | C28: NP-đầy đủ | D28: 98 | E28: =INDEX(Roadmap!$P$5:$P$104,D28) -> Chưa bắt đầu | F28: P, NP, rút gọn, bài toán NP-đầy đủ điển hình (đối chiếu slide) | G28: Gợi ý theo tên file

Sheet Cpp_vs_Java
A1: BẢNG ĐỐI CHIẾU C++ ↔ JAVA CHO LẬP TRÌNH THUẬT TOÁN
A3: Mục đích | B3: C++ (STL) | C3: Java | D3: Độ phức tạp | E3: Lưu ý
A4: Mảng động | B4: vector<int> a; a.push_back(x) | C4: ArrayList<Integer> a; a.add(x) | int[] | D4: O(1) trung bình | E4: Java: List<Integer> tốn bộ nhớ vì boxing, ưu tiên int[] khi biết kích thước
A5: Sắp xếp | B5: sort(a.begin(), a.end()) | C5: Arrays.sort(a) | Collections.sort(list) | D5: O(n log n) | E5: Arrays.sort(int[]) là dual-pivot quicksort; dùng Integer[] hoặc xáo trộn nếu lo test chống quicksort
A6: Comparator tuỳ biến | B6: sort(v.begin(), v.end(), [](auto&a, auto&b){ return a.x < b.x; }) | C6: Arrays.sort(arr, (a,b) -> Integer.compare(a[0], b[0])) | D6: O(n log n) | E6: Java: không dùng a[0]-b[0] vì có thể tràn số
A7: Tìm kiếm nhị phân | B7: lower_bound / upper_bound / binary_search | C7: Arrays.binarySearch (không có lower_bound – tự viết) | D7: O(log n) | E7: Tự viết lower_bound bằng Java để dùng chung mọi bài
A8: Hash map / set | B8: unordered_map, unordered_set | C8: HashMap, HashSet | D8: O(1) trung bình | E8: Dữ liệu đối kháng có thể làm hash chậm; cân nhắc map/TreeMap
A9: Map / set có thứ tự | B9: map, set | C9: TreeMap, TreeSet (floorKey, ceilingKey, higher, lower) | D9: O(log n)
A10: Multiset | B10: multiset | C10: TreeMap<Integer,Integer> đếm số lần | D10: O(log n) | E10: Xoá một phần tử: giảm count, nếu 0 thì remove
A11: Stack | B11: stack<int> | C11: Deque<Integer> st = new ArrayDeque<>() | D11: O(1) | E11: Tránh class Stack (cũ, đồng bộ hoá chậm)
A12: Queue / Deque | B12: queue<int>, deque<int> | C12: Queue<Integer> q = new ArrayDeque<>() | D12: O(1) | E12: ArrayDeque không cho phép null
A13: Priority queue | B13: priority_queue<int> (max-heap mặc định) | C13: PriorityQueue<Integer> (min-heap mặc định) | D13: O(log n) | E13: Max-heap Java: new PriorityQueue<>(Collections.reverseOrder())
A14: Pair / bộ giá trị | B14: pair<int,int>, tuple | C14: int[]{a,b} | record Pair(int a, int b) | E14: Java: int[] trong HashSet so sánh theo tham chiếu → dùng record hoặc mã hoá thành long
A15: Xâu có thể sửa | B15: string s; s += c | C15: StringBuilder sb; sb.append(c) | D15: O(1) trung bình | E15: Java: String bất biến, nối bằng + trong vòng lặp là O(n²)
A16: Số lớn | B16: __int128 hoặc tự viết | C16: BigInteger, BigDecimal | E16: Thi thường giới hạn long; chỉ dùng BigInteger khi cần
A17: Kiểu 64-bit | B17: long long | C17: long | E17: Khai báo hằng: 1LL<<40 (C++), 1L<<40 (Java)
A18: Giá trị vô cực | B18: INT_MAX, LLONG_MAX, 1e9, 1e18 | C18: Integer.MAX_VALUE, Long.MAX_VALUE | E18: Cẩn thận INF + INF tràn số; dùng INF = 1e9 hoặc 4e18/2
A19: Điền mảng | B19: fill(a, a+n, v) / memset | C19: Arrays.fill(a, v) | D19: O(n) | E19: memset chỉ an toàn với 0 và −1
A20: Mảng 2 chiều | B20: vector<vector<int>> g(n, vector<int>(m)) | C20: int[][] g = new int[n][m]
A21: Đồ thị danh sách kề | B21: vector<vector<pair<int,int>>> adj(n) | C21: List<int[]>[] adj = new List[n] | E21: Java: cảnh báo generic array, khởi tạo từng phần tử bằng new ArrayList<>()
A22: Đọc dữ liệu nhanh | B22: ios::sync_with_stdio(false); cin.tie(nullptr); | C22: BufferedReader + StringTokenizer | StreamTokenizer | E22: Java: dùng PrintWriter / StringBuilder để xuất
A23: Hoán vị kế tiếp | B23: next_permutation | C23: Tự viết | D23: O(n)
A24: Đếm bit | B24: __builtin_popcount, __builtin_clz | C24: Integer.bitCount, Integer.numberOfLeadingZeros | D24: O(1) | E24: log2 nguyên: 31 − clz(x) (C++/Java) hoặc __lg(x) (C++)
A25: Min / max của mảng | B25: *min_element(a.begin(), a.end()) | C25: Arrays.stream(a).min().getAsInt() | Collections.max(list) | D25: O(n)
A26: Sao chép mảng | B26: vector<int> b = a; | C26: Arrays.copyOf(a, n) | a.clone() | D26: O(n) | E26: Java: gán b = a chỉ sao chép tham chiếu
A27: Loại phần tử trùng | B27: sort + unique + erase | C27: TreeSet | stream().distinct() | D27: O(n log n)
A28: Độ sâu đệ quy | B28: ulimit -s (thường 8MB) | C28: -Xss | new Thread(null, r, "", 1<<26).start() | E28: Cây lệch 10^5 – 10^6 nút có thể tràn stack
A29: Đo thời gian | B29: chrono::steady_clock | C29: System.nanoTime()

Sheet HuongDan
A1: HƯỚNG DẪN SỬ DỤNG
A3: CÁCH DÙNG NHANH
A4: 1. | B4: Vào Dashboard, ô B4 = ngày bắt đầu (mặc định 05/10/2026, sửa theo ngày bạn thực sự bắt đầu). Toàn bộ ngày dự kiến tự dịch theo.
A5: 2. | B5: Mỗi ngày mở sheet Roadmap, tìm dòng nền xanh nhạt (hôm nay): đọc nội dung lý thuyết, xem gợi ý C++/Java, giải các bài trong cột Bài LeetCode.
A6: 3. | B6: Sau khi giải bài, sang sheet LeetCode: chọn Trạng thái = Xong, tick C++ ✓ / Java ✓, điền Ngày giải, Số lần thử, Ghi chú ý tưởng. Ngày ôn lại tự sinh.
A7: 4. | B7: Cuối ngày: ở Roadmap tick Lý thuyết ✓, C++ ✓, Java ✓ (đã tự cài thuật toán của ngày đó ở từng ngôn ngữ). Ngày chuyển sang Hoàn thành khi đủ 3 dấu ✓ và xong mọi bài trong kế hoạch.
A8: 5. | B8: Điền sheet NhatKy: Giờ học thực tế, Tự đánh giá, Điều đã học, Vướng mắc. Số bài giải và chuỗi ngày học tự tính.
A9: 6. | B9: Sheet Slide: tick 4 cột cho từng thuật toán trong slide. Sheet Cpp_vs_Java: tra cứu nhanh khi chuyển ngôn ngữ.
A10: QUY TẮC MÀU Ô
A11: Nền vàng, chữ xanh | B11: Ô bạn nhập (ngày bắt đầu, chu kỳ ôn, ✓, trạng thái, giờ học, ghi chú…).
A12: Nền trắng/xám | B12: Công thức hoặc dữ liệu cố định, không cần sửa.
A13: Dòng xanh nhạt | B13: Ngày hôm nay (so với ngày bắt đầu).
A14: Trạng thái ngày | B14: Hoàn thành (xanh) / Đang học (vàng) / Trễ hạn (đỏ: quá ngày dự kiến mà chưa hoàn thành) / Chưa bắt đầu (xám).
A15: CHIẾN LƯỢC C++ & JAVA
A16: Gợi ý | B16: Giải bài bằng ngôn ngữ nào tuỳ bạn, nhưng với mỗi ngày hãy cài lại ít nhất 1 bài (hoặc template của chủ đề) bằng ngôn ngữ còn lại, rồi tick cả hai cột.
A17: Ôn tập ngắt quãng | B17: Mỗi bài đã giải có 3 mốc ôn (mặc định +3, +7, +14 ngày; chỉnh ở Dashboard B5:B7). Cột Lần ôn kế tiếp tô cam khi đến hạn.
A18: Quy tắc 3 lần thử | B18: Sau 3 lần tự thử mà chưa ra thì xem lời giải, ghi ý tưởng vào cột Ghi chú, đặt trạng thái Cần ôn rồi làm lại sau 1-2 ngày.
A19: GIẢ ĐỊNH
A20: Thời gian | B20: 100 ngày liên tục, khoảng 3 giờ/ngày (cột Giờ KH, sửa được); ngày 99-100 là 4 giờ.
A21: Số bài | B21: 338 bài LeetCode, phân bổ khoảng 3-4 bài/ngày; một số ngày ôn tập có ít bài hơn.
A22: Slide | B22: Tuần 2-4 và tuần 11 được lập từ nội dung slide đã đọc; các tuần còn lại (1, 5-10, 12-15) dựa trên tên file, hãy đối chiếu rồi sửa sheet Slide và Roadmap.
A23: Link bài | B23: Mỗi link mở trang tìm kiếm LeetCode theo tên bài; độ khó và tên bài nên được kiểm tra lại trên LeetCode vì có thể thay đổi.
A24: Bài ngoài LeetCode | B24: LeetCode ít bài về Max Flow, CVRP, bin packing nên cột "Bài ngoài LeetCode" gợi ý thêm nguồn khác (SPOJ, CSES, hệ thống chấm của lớp).
A26: VÍ DỤ CÁCH ĐIỀN (1 dòng sheet LeetCode)
A27: Trạng thái | B27: Xong
A28: C++ ✓ / Java ✓ | B28: ✓ / ✓
A29: Ngày giải | B29: 07/10/2026
A30: Số lần thử | B30: 2
A31: Ghi chú | B31: Hash map lưu giá trị → chỉ số, O(n) thời gian, O(n) bộ nhớ
